{
 "cells": [
  {
   "cell_type": "code",
   "execution_count": 4,
   "metadata": {
    "collapsed": true
   },
   "outputs": [],
   "source": [
    "import sys\n",
    "import os\n",
    "import socket\n",
    "from socket import error as SocketError\n",
    "import errno\n",
    "import time\n",
    "from contextlib import suppress\n",
    "import traceback\n",
    "import struct\n",
    "import ctypes"
   ]
  },
  {
   "cell_type": "code",
   "execution_count": 8,
   "metadata": {
    "collapsed": false
   },
   "outputs": [
    {
     "ename": "OSError",
     "evalue": "[Errno 107] Transport endpoint is not connected",
     "output_type": "error",
     "traceback": [
      "\u001b[1;31m---------------------------------------------------------------------------\u001b[0m",
      "\u001b[1;31mConnectionRefusedError\u001b[0m                    Traceback (most recent call last)",
      "\u001b[1;32m<ipython-input-8-4265e7406300>\u001b[0m in \u001b[0;36mmain\u001b[1;34m(argv)\u001b[0m\n\u001b[0;32m      9\u001b[0m         \u001b[0mS\u001b[0m\u001b[1;33m=\u001b[0m\u001b[0msocket\u001b[0m\u001b[1;33m.\u001b[0m\u001b[0msocket\u001b[0m\u001b[1;33m(\u001b[0m\u001b[0msocket\u001b[0m\u001b[1;33m.\u001b[0m\u001b[0mAF_INET\u001b[0m\u001b[1;33m,\u001b[0m\u001b[0msocket\u001b[0m\u001b[1;33m.\u001b[0m\u001b[0mSOCK_STREAM\u001b[0m\u001b[1;33m)\u001b[0m\u001b[1;33m\u001b[0m\u001b[0m\n\u001b[1;32m---> 10\u001b[1;33m         \u001b[0mS\u001b[0m\u001b[1;33m.\u001b[0m\u001b[0mconnect\u001b[0m\u001b[1;33m(\u001b[0m\u001b[1;33m(\u001b[0m\u001b[1;34m\"127.0.0.1\"\u001b[0m\u001b[1;33m,\u001b[0m\u001b[1;36m55556\u001b[0m\u001b[1;33m)\u001b[0m\u001b[1;33m)\u001b[0m\u001b[1;33m\u001b[0m\u001b[0m\n\u001b[0m\u001b[0;32m     11\u001b[0m         \u001b[0mS\u001b[0m\u001b[1;33m.\u001b[0m\u001b[0msettimeout\u001b[0m\u001b[1;33m(\u001b[0m\u001b[0mwaitt\u001b[0m\u001b[1;33m)\u001b[0m\u001b[1;33m\u001b[0m\u001b[0m\n",
      "\u001b[1;31mConnectionRefusedError\u001b[0m: [Errno 111] Connection refused",
      "\nDuring handling of the above exception, another exception occurred:\n",
      "\u001b[1;31mOSError\u001b[0m                                   Traceback (most recent call last)",
      "\u001b[1;32m<ipython-input-8-4265e7406300>\u001b[0m in \u001b[0;36m<module>\u001b[1;34m()\u001b[0m\n\u001b[0;32m     31\u001b[0m \u001b[1;33m\u001b[0m\u001b[0m\n\u001b[0;32m     32\u001b[0m \u001b[1;32mif\u001b[0m \u001b[0m__name__\u001b[0m\u001b[1;33m==\u001b[0m\u001b[1;34m\"__main__\"\u001b[0m\u001b[1;33m:\u001b[0m\u001b[1;33m\u001b[0m\u001b[0m\n\u001b[1;32m---> 33\u001b[1;33m     \u001b[0mmain\u001b[0m\u001b[1;33m(\u001b[0m\u001b[0msys\u001b[0m\u001b[1;33m.\u001b[0m\u001b[0margv\u001b[0m\u001b[1;33m[\u001b[0m\u001b[1;36m1\u001b[0m\u001b[1;33m:\u001b[0m\u001b[1;33m]\u001b[0m\u001b[1;33m)\u001b[0m\u001b[1;33m\u001b[0m\u001b[0m\n\u001b[0m",
      "\u001b[1;32m<ipython-input-8-4265e7406300>\u001b[0m in \u001b[0;36mmain\u001b[1;34m(argv)\u001b[0m\n\u001b[0;32m     26\u001b[0m                 \u001b[0mprint\u001b[0m\u001b[1;33m(\u001b[0m\u001b[1;34m\"no response recieved in {} seconds\"\u001b[0m\u001b[1;33m.\u001b[0m\u001b[0mformat\u001b[0m\u001b[1;33m(\u001b[0m\u001b[0ms\u001b[0m\u001b[1;33m)\u001b[0m\u001b[1;33m)\u001b[0m\u001b[1;33m\u001b[0m\u001b[0m\n\u001b[0;32m     27\u001b[0m     \u001b[1;32mfinally\u001b[0m\u001b[1;33m:\u001b[0m\u001b[1;33m\u001b[0m\u001b[0m\n\u001b[1;32m---> 28\u001b[1;33m         \u001b[0mS\u001b[0m\u001b[1;33m.\u001b[0m\u001b[0mshutdown\u001b[0m\u001b[1;33m(\u001b[0m\u001b[0msocket\u001b[0m\u001b[1;33m.\u001b[0m\u001b[0mSHUT_RDWR\u001b[0m\u001b[1;33m)\u001b[0m\u001b[1;33m\u001b[0m\u001b[0m\n\u001b[0m\u001b[0;32m     29\u001b[0m         \u001b[0mS\u001b[0m\u001b[1;33m.\u001b[0m\u001b[0mclose\u001b[0m\u001b[1;33m(\u001b[0m\u001b[1;33m)\u001b[0m\u001b[1;33m\u001b[0m\u001b[0m\n\u001b[0;32m     30\u001b[0m         \u001b[0mprint\u001b[0m\u001b[1;33m(\u001b[0m\u001b[1;34m\"client closing\"\u001b[0m\u001b[1;33m)\u001b[0m\u001b[1;33m\u001b[0m\u001b[0m\n",
      "\u001b[1;31mOSError\u001b[0m: [Errno 107] Transport endpoint is not connected"
     ]
    }
   ],
   "source": [
    "class RemoteSocketClosed(Exception):\n",
    "    pass\n",
    "\n",
    "def main(argv):\n",
    "    key=b\"asdf\"\n",
    "    mtype=ctypes.c_uint32(1)\n",
    "    waitt=5\n",
    "    try:\n",
    "        S=socket.socket(socket.AF_INET,socket.SOCK_STREAM)\n",
    "        S.connect((\"127.0.0.1\",55556))\n",
    "        S.settimeout(waitt)\n",
    "        while(True):\n",
    "            try:\n",
    "                message=input(\"enter message: \")\n",
    "                if message==\"close\":\n",
    "                    break\n",
    "                message=message.encode()\n",
    "                message=key+mtype+ctypes.c_uint32(len(message))+message\n",
    "                print(message)\n",
    "                S.sendall(message)\n",
    "                chunk=S.recv(4096)\n",
    "                if len(chunk) == 0:\n",
    "                    raise RemoteSocketClosed\n",
    "                print(chunk)\n",
    "            except socket.timeout:\n",
    "                print(\"no response recieved in {} seconds\".format(s))\n",
    "    finally:\n",
    "        S.shutdown(socket.SHUT_RDWR)\n",
    "        S.close()\n",
    "        print(\"client closing\")\n",
    "\n",
    "if __name__==\"__main__\":\n",
    "    main(sys.argv[1:])"
   ]
  }
 ],
 "metadata": {
  "kernelspec": {
   "display_name": "Python 3",
   "language": "python",
   "name": "python3"
  },
  "language_info": {
   "codemirror_mode": {
    "name": "ipython",
    "version": 3
   },
   "file_extension": ".py",
   "mimetype": "text/x-python",
   "name": "python",
   "nbconvert_exporter": "python",
   "pygments_lexer": "ipython3",
   "version": "3.4.0"
  }
 },
 "nbformat": 4,
 "nbformat_minor": 0
}
